Workbook

Sheet DATASETS
A1: DATASETS – MMDA AADT and MMARAS crash counts, NCR roads, 2015–2024, with previous-year crashes (Prev) and road size
A2: All AADT, crash, length and lane values are live links to SOURCE_DATA (unchanged copy of AADT_MMARAS_DATASETS.xlsx). Prev is a lookup on ROAD + (YEAR − 1); nothing is imputed.
A4: Road | B4: Year | C4: AADT (vehicles/day) | D4: Actual MMARAS crashes (count/year) | E4: Dataset classification | F4: Road length (km) | G4: Total lanes (average) | H4: Total lanes-kilometers | I4: Prev = crashes of same road in Year − 1 | J4: How Prev was obtained | K4: Used in Prev-based models? | M4: SUMMARY COUNTS (formulas) | N4: Value
A5: =SOURCE_DATA!A5 -> PRES. QUIRINO AVE. | B5: 2015 | C5: =SOURCE_DATA!B5 -> 119824 | D5: =SOURCE_DATA!L5 -> 887 | E5: Training | F5: =SOURCE_DATA!W5 -> 3.6 | G5: =SOURCE_DATA!X5 -> 8 | H5: =SOURCE_DATA!Y5 -> 28.8 | I5: =IF(COUNTIFS($A$5:$A$144,A5,$B$5:$B$144,B5-1)=1,SUMIFS($D$5:$D$144,$A$5:$A$144,A5,$B$5:$B$144,B5-1),"N/A") -> N/A | J5: =IF(ISNUMBER(I5),"Actual "&(B5-1)&" crashes of this road","Unavailable – no "&(B5-1)&" MMARAS record (not imputed)") -> Unavailable – no 2014 MMARAS record (not imputed) | K5: =IF(ISNUMBER(I5),"Yes","No – excluded") -> No – excluded | M5: Eligible roads (training + EDSA) | N5: =SUMPRODUCT(1/COUNTIF($A$5:$A$144,$A$5:$A$144)) -> 14
A6: =SOURCE_DATA!A5 -> PRES. QUIRINO AVE. | B6: 2016 | C6: =SOURCE_DATA!C5 -> 117482 | D6: =SOURCE_DATA!M5 -> 1005 | E6: Training | F6: =SOURCE_DATA!W5 -> 3.6 | G6: =SOURCE_DATA!X5 -> 8 | H6: =SOURCE_DATA!Y5 -> 28.8 | I6: =IF(COUNTIFS($A$5:$A$144,A6,$B$5:$B$144,B6-1)=1,SUMIFS($D$5:$D$144,$A$5:$A$144,A6,$B$5:$B$144,B6-1),"N/A") -> 887 | J6: =IF(ISNUMBER(I6),"Actual "&(B6-1)&" crashes of this road","Unavailable – no "&(B6-1)&" MMARAS record (not imputed)") -> Actual 2015 crashes of this road | K6: =IF(ISNUMBER(I6),"Yes","No – excluded") -> Yes | M6: Eligible TRAINING roads (EDSA excluded) | N6: =SUMPRODUCT(($E$5:$E$144="Training")/COUNTIFS($A$5:$A$144,$A$5:$A$144,$E$5:$E$144,$E$5:$E$144)) -> 13
A7: =SOURCE_DATA!A5 -> PRES. QUIRINO AVE. | B7: 2017 | C7: =SOURCE_DATA!D5 -> 105118 | D7: =SOURCE_DATA!N5 -> 868 | E7: Training | F7: =SOURCE_DATA!W5 -> 3.6 | G7: =SOURCE_DATA!X5 -> 8 | H7: =SOURCE_DATA!Y5 -> 28.8 | I7: =IF(COUNTIFS($A$5:$A$144,A7,$B$5:$B$144,B7-1)=1,SUMIFS($D$5:$D$144,$A$5:$A$144,A7,$B$5:$B$144,B7-1),"N/A") -> 1005 | J7: =IF(ISNUMBER(I7),"Actual "&(B7-1)&" crashes of this road","Unavailable – no "&(B7-1)&" MMARAS record (not imputed)") -> Actual 2016 crashes of this road | K7: =IF(ISNUMBER(I7),"Yes","No – excluded") -> Yes | M7: Training road-years in the source (2015–2024) | N7: =COUNTIF($E$5:$E$144,"Training") -> 130
A8: =SOURCE_DATA!A5 -> PRES. QUIRINO AVE. | B8: 2018 | C8: =SOURCE_DATA!E5 -> 108592 | D8: =SOURCE_DATA!O5 -> 953 | E8: Training | F8: =SOURCE_DATA!W5 -> 3.6 | G8: =SOURCE_DATA!X5 -> 8 | H8: =SOURCE_DATA!Y5 -> 28.8 | I8: =IF(COUNTIFS($A$5:$A$144,A8,$B$5:$B$144,B8-1)=1,SUMIFS($D$5:$D$144,$A$5:$A$144,A8,$B$5:$B$144,B8-1),"N/A") -> 868 | J8: =IF(ISNUMBER(I8),"Actual "&(B8-1)&" crashes of this road","Unavailable – no "&(B8-1)&" MMARAS record (not imputed)") -> Actual 2017 crashes of this road | K8: =IF(ISNUMBER(I8),"Yes","No – excluded") -> Yes | M8: EDSA test road-years in the source (2015–2024) | N8: =COUNTIF($E$5:$E$144,"EDSA Test") -> 10
A9: =SOURCE_DATA!A5 -> PRES. QUIRINO AVE. | B9: 2019 | C9: =SOURCE_DATA!F5 -> 116767 | D9: =SOURCE_DATA!P5 -> 1127 | E9: Training | F9: =SOURCE_DATA!W5 -> 3.6 | G9: =SOURCE_DATA!X5 -> 8 | H9: =SOURCE_DATA!Y5 -> 28.8 | I9: =IF(COUNTIFS($A$5:$A$144,A9,$B$5:$B$144,B9-1)=1,SUMIFS($D$5:$D$144,$A$5:$A$144,A9,$B$5:$B$144,B9-1),"N/A") -> 953 | J9: =IF(ISNUMBER(I9),"Actual "&(B9-1)&" crashes of this road","Unavailable – no "&(B9-1)&" MMARAS record (not imputed)") -> Actual 2018 crashes of this road | K9: =IF(ISNUMBER(I9),"Yes","No – excluded") -> Yes | M9: Training observations USED (Prev available, 2016–2024) | N9: =COUNTIFS($E$5:$E$144,"Training",$K$5:$K$144,"Yes") -> 117
A10: =SOURCE_DATA!A5 -> PRES. QUIRINO AVE. | B10: 2020 | C10: =SOURCE_DATA!G5 -> 84967 | D10: =SOURCE_DATA!Q5 -> 484 | E10: Training | F10: =SOURCE_DATA!W5 -> 3.6 | G10: =SOURCE_DATA!X5 -> 8 | H10: =SOURCE_DATA!Y5 -> 28.8 | I10: =IF(COUNTIFS($A$5:$A$144,A10,$B$5:$B$144,B10-1)=1,SUMIFS($D$5:$D$144,$A$5:$A$144,A10,$B$5:$B$144,B10-1),"N/A") -> 1127 | J10: =IF(ISNUMBER(I10),"Actual "&(B10-1)&" crashes of this road","Unavailable – no "&(B10-1)&" MMARAS record (not imputed)") -> Actual 2019 crashes of this road | K10: =IF(ISNUMBER(I10),"Yes","No – excluded") -> Yes | M10: EDSA test observations USED (Prev available, 2016–2024) | N10: =COUNTIFS($E$5:$E$144,"EDSA Test",$K$5:$K$144,"Yes") -> 9
A11: =SOURCE_DATA!A5 -> PRES. QUIRINO AVE. | B11: 2021 | C11: =SOURCE_DATA!H5 -> 72582 | D11: =SOURCE_DATA!R5 -> 350 | E11: Training | F11: =SOURCE_DATA!W5 -> 3.6 | G11: =SOURCE_DATA!X5 -> 8 | H11: =SOURCE_DATA!Y5 -> 28.8 | I11: =IF(COUNTIFS($A$5:$A$144,A11,$B$5:$B$144,B11-1)=1,SUMIFS($D$5:$D$144,$A$5:$A$144,A11,$B$5:$B$144,B11-1),"N/A") -> 484 | J11: =IF(ISNUMBER(I11),"Actual "&(B11-1)&" crashes of this road","Unavailable – no "&(B11-1)&" MMARAS record (not imputed)") -> Actual 2020 crashes of this road | K11: =IF(ISNUMBER(I11),"Yes","No – excluded") -> Yes | M11: Observations excluded because Prev is unavailable (2015) | N11: =COUNTIF($K$5:$K$144,"No*") -> 14
A12: =SOURCE_DATA!A5 -> PRES. QUIRINO AVE. | B12: 2022 | C12: =SOURCE_DATA!I5 -> 147617 | D12: =SOURCE_DATA!S5 -> 808 | E12: Training | F12: =SOURCE_DATA!W5 -> 3.6 | G12: =SOURCE_DATA!X5 -> 8 | H12: =SOURCE_DATA!Y5 -> 28.8 | I12: =IF(COUNTIFS($A$5:$A$144,A12,$B$5:$B$144,B12-1)=1,SUMIFS($D$5:$D$144,$A$5:$A$144,A12,$B$5:$B$144,B12-1),"N/A") -> 350 | J12: =IF(ISNUMBER(I12),"Actual "&(B12-1)&" crashes of this road","Unavailable – no "&(B12-1)&" MMARAS record (not imputed)") -> Actual 2021 crashes of this road | K12: =IF(ISNUMBER(I12),"Yes","No – excluded") -> Yes | M12: Years covered by AADT and MMARAS | N12: =MIN($B$5:$B$144)&"–"&MAX($B$5:$B$144) -> 2015–2024
A13: =SOURCE_DATA!A5 -> PRES. QUIRINO AVE. | B13: 2023 | C13: =SOURCE_DATA!J5 -> 177881 | D13: =SOURCE_DATA!T5 -> 951 | E13: Training | F13: =SOURCE_DATA!W5 -> 3.6 | G13: =SOURCE_DATA!X5 -> 8 | H13: =SOURCE_DATA!Y5 -> 28.8 | I13: =IF(COUNTIFS($A$5:$A$144,A13,$B$5:$B$144,B13-1)=1,SUMIFS($D$5:$D$144,$A$5:$A$144,A13,$B$5:$B$144,B13-1),"N/A") -> 808 | J13: =IF(ISNUMBER(I13),"Actual "&(B13-1)&" crashes of this road","Unavailable – no "&(B13-1)&" MMARAS record (not imputed)") -> Actual 2022 crashes of this road | K13: =IF(ISNUMBER(I13),"Yes","No – excluded") -> Yes
A14: =SOURCE_DATA!A5 -> PRES. QUIRINO AVE. | B14: 2024 | C14: =SOURCE_DATA!K5 -> 195138 | D14: =SOURCE_DATA!U5 -> 1041 | E14: Training | F14: =SOURCE_DATA!W5 -> 3.6 | G14: =SOURCE_DATA!X5 -> 8 | H14: =SOURCE_DATA!Y5 -> 28.8 | I14: =IF(COUNTIFS($A$5:$A$144,A14,$B$5:$B$144,B14-1)=1,SUMIFS($D$5:$D$144,$A$5:$A$144,A14,$B$5:$B$144,B14-1),"N/A") -> 951 | J14: =IF(ISNUMBER(I14),"Actual "&(B14-1)&" crashes of this road","Unavailable – no "&(B14-1)&" MMARAS record (not imputed)") -> Actual 2023 crashes of this road | K14: =IF(ISNUMBER(I14),"Yes","No – excluded") -> Yes
A15: =SOURCE_DATA!A7 -> C.P. GARCIA /KATIPUNAN AVE. / TANDANG SORA | B15: 2015 | C15: =SOURCE_DATA!B7 -> 194119 | D15: =SOURCE_DATA!L7 -> 4598 | E15: Training | F15: =SOURCE_DATA!W7 -> 43.87 | G15: =SOURCE_DATA!X7 -> 10 | H15: =SOURCE_DATA!Y7 -> 438.7 | I15: =IF(COUNTIFS($A$5:$A$144,A15,$B$5:$B$144,B15-1)=1,SUMIFS($D$5:$D$144,$A$5:$A$144,A15,$B$5:$B$144,B15-1),"N/A") -> N/A | J15: =IF(ISNUMBER(I15),"Actual "&(B15-1)&" crashes of this road","Unavailable – no "&(B15-1)&" MMARAS record (not imputed)") -> Unavailable – no 2014 MMARAS record (not imputed) | K15: =IF(ISNUMBER(I15),"Yes","No – excluded") -> No – excluded
A16: =SOURCE_DATA!A7 -> C.P. GARCIA /KATIPUNAN AVE. / TANDANG SORA | B16: 2016 | C16: =SOURCE_DATA!C7 -> 218155 | D16: =SOURCE_DATA!M7 -> 5911 | E16: Training | F16: =SOURCE_DATA!W7 -> 43.87 | G16: =SOURCE_DATA!X7 -> 10 | H16: =SOURCE_DATA!Y7 -> 438.7 | I16: =IF(COUNTIFS($A$5:$A$144,A16,$B$5:$B$144,B16-1)=1,SUMIFS($D$5:$D$144,$A$5:$A$144,A16,$B$5:$B$144,B16-1),"N/A") -> 4598 | J16: =IF(ISNUMBER(I16),"Actual "&(B16-1)&" crashes of this road","Unavailable – no "&(B16-1)&" MMARAS record (not imputed)") -> Actual 2015 crashes of this road | K16: =IF(ISNUMBER(I16),"Yes","No – excluded") -> Yes | M16: DATA VERIFICATION AND HANDLING (documented, nothing altered)
A17: =SOURCE_DATA!A7 -> C.P. GARCIA /KATIPUNAN AVE. / TANDANG SORA | B17: 2017 | C17: =SOURCE_DATA!D7 -> 218751 | D17: =SOURCE_DATA!N7 -> 5794 | E17: Training | F17: =SOURCE_DATA!W7 -> 43.87 | G17: =SOURCE_DATA!X7 -> 10 | H17: =SOURCE_DATA!Y7 -> 438.7 | I17: =IF(COUNTIFS($A$5:$A$144,A17,$B$5:$B$144,B17-1)=1,SUMIFS($D$5:$D$144,$A$5:$A$144,A17,$B$5:$B$144,B17-1),"N/A") -> 5911 | J17: =IF(ISNUMBER(I17),"Actual "&(B17-1)&" crashes of this road","Unavailable – no "&(B17-1)&" MMARAS record (not imputed)") -> Actual 2016 crashes of this road | K17: =IF(ISNUMBER(I17),"Yes","No – excluded") -> Yes | M17: 1. Years available in BOTH datasets: AADT 2015–2024 and MMARAS 2015–2024. The source has NO 2014 MMARAS crash counts, so the 2015 record of every road has no Prev.
A18: =SOURCE_DATA!A7 -> C.P. GARCIA /KATIPUNAN AVE. / TANDANG SORA | B18: 2018 | C18: =SOURCE_DATA!E7 -> 235744 | D18: =SOURCE_DATA!O7 -> 8252 | E18: Training | F18: =SOURCE_DATA!W7 -> 43.87 | G18: =SOURCE_DATA!X7 -> 10 | H18: =SOURCE_DATA!Y7 -> 438.7 | I18: =IF(COUNTIFS($A$5:$A$144,A18,$B$5:$B$144,B18-1)=1,SUMIFS($D$5:$D$144,$A$5:$A$144,A18,$B$5:$B$144,B18-1),"N/A") -> 5794 | J18: =IF(ISNUMBER(I18),"Actual "&(B18-1)&" crashes of this road","Unavailable – no "&(B18-1)&" MMARAS record (not imputed)") -> Actual 2017 crashes of this road | K18: =IF(ISNUMBER(I18),"Yes","No – excluded") -> Yes | M18: 2015 rows are kept here for transparency, marked "No – excluded", and are NOT used in any model that needs Prev. 2014 values were NOT invented.
A19: =SOURCE_DATA!A7 -> C.P. GARCIA /KATIPUNAN AVE. / TANDANG SORA | B19: 2019 | C19: =SOURCE_DATA!F7 -> 236060 | D19: =SOURCE_DATA!P7 -> 8735 | E19: Training | F19: =SOURCE_DATA!W7 -> 43.87 | G19: =SOURCE_DATA!X7 -> 10 | H19: =SOURCE_DATA!Y7 -> 438.7 | I19: =IF(COUNTIFS($A$5:$A$144,A19,$B$5:$B$144,B19-1)=1,SUMIFS($D$5:$D$144,$A$5:$A$144,A19,$B$5:$B$144,B19-1),"N/A") -> 8252 | J19: =IF(ISNUMBER(I19),"Actual "&(B19-1)&" crashes of this road","Unavailable – no "&(B19-1)&" MMARAS record (not imputed)") -> Actual 2018 crashes of this road | K19: =IF(ISNUMBER(I19),"Yes","No – excluded") -> Yes | M19: 2. Roads: AADT file lists 20 roads; 5 (RECTO, MENDOZA, ARANETA, SHAW, A. BONIFACIO) + 1 blank row have no MMARAS record → excluded.
A20: =SOURCE_DATA!A7 -> C.P. GARCIA /KATIPUNAN AVE. / TANDANG SORA | B20: 2020 | C20: =SOURCE_DATA!G7 -> 192418 | D20: =SOURCE_DATA!Q7 -> 5208 | E20: Training | F20: =SOURCE_DATA!W7 -> 43.87 | G20: =SOURCE_DATA!X7 -> 10 | H20: =SOURCE_DATA!Y7 -> 438.7 | I20: =IF(COUNTIFS($A$5:$A$144,A20,$B$5:$B$144,B20-1)=1,SUMIFS($D$5:$D$144,$A$5:$A$144,A20,$B$5:$B$144,B20-1),"N/A") -> 8735 | J20: =IF(ISNUMBER(I20),"Actual "&(B20-1)&" crashes of this road","Unavailable – no "&(B20-1)&" MMARAS record (not imputed)") -> Actual 2019 crashes of this road | K20: =IF(ISNUMBER(I20),"Yes","No – excluded") -> Yes | M20: 3. MMARAS records Magsaysay + Aurora Blvd. as ONE road (R-6, count stored on the Magsaysay row). R-6 AADT = mean of the two AADT values (as in the study paper);
A21: =SOURCE_DATA!A7 -> C.P. GARCIA /KATIPUNAN AVE. / TANDANG SORA | B21: 2021 | C21: =SOURCE_DATA!H7 -> 212285 | D21: =SOURCE_DATA!R7 -> 5769 | E21: Training | F21: =SOURCE_DATA!W7 -> 43.87 | G21: =SOURCE_DATA!X7 -> 10 | H21: =SOURCE_DATA!Y7 -> 438.7 | I21: =IF(COUNTIFS($A$5:$A$144,A21,$B$5:$B$144,B21-1)=1,SUMIFS($D$5:$D$144,$A$5:$A$144,A21,$B$5:$B$144,B21-1),"N/A") -> 5208 | J21: =IF(ISNUMBER(I21),"Actual "&(B21-1)&" crashes of this road","Unavailable – no "&(B21-1)&" MMARAS record (not imputed)") -> Actual 2020 crashes of this road | K21: =IF(ISNUMBER(I21),"Yes","No – excluded") -> Yes | M21: R-6 length = 2.2 + 9.0 km; R-6 lanes-km = 2.2×10 + 9.0×7 = 85.0; R-6 average lanes = lanes-km ÷ length.
A22: =SOURCE_DATA!A7 -> C.P. GARCIA /KATIPUNAN AVE. / TANDANG SORA | B22: 2022 | C22: =SOURCE_DATA!I7 -> 211819 | D22: =SOURCE_DATA!S7 -> 7255 | E22: Training | F22: =SOURCE_DATA!W7 -> 43.87 | G22: =SOURCE_DATA!X7 -> 10 | H22: =SOURCE_DATA!Y7 -> 438.7 | I22: =IF(COUNTIFS($A$5:$A$144,A22,$B$5:$B$144,B22-1)=1,SUMIFS($D$5:$D$144,$A$5:$A$144,A22,$B$5:$B$144,B22-1),"N/A") -> 5769 | J22: =IF(ISNUMBER(I22),"Actual "&(B22-1)&" crashes of this road","Unavailable – no "&(B22-1)&" MMARAS record (not imputed)") -> Actual 2021 crashes of this road | K22: =IF(ISNUMBER(I22),"Yes","No – excluded") -> Yes | M22: 4. 13 non-EDSA roads = model-development (training) roads; EDSA is kept out of training and used only as the independent test road.
A23: =SOURCE_DATA!A7 -> C.P. GARCIA /KATIPUNAN AVE. / TANDANG SORA | B23: 2023 | C23: =SOURCE_DATA!J7 -> 238695 | D23: =SOURCE_DATA!T7 -> 8119 | E23: Training | F23: =SOURCE_DATA!W7 -> 43.87 | G23: =SOURCE_DATA!X7 -> 10 | H23: =SOURCE_DATA!Y7 -> 438.7 | I23: =IF(COUNTIFS($A$5:$A$144,A23,$B$5:$B$144,B23-1)=1,SUMIFS($D$5:$D$144,$A$5:$A$144,A23,$B$5:$B$144,B23-1),"N/A") -> 7255 | J23: =IF(ISNUMBER(I23),"Actual "&(B23-1)&" crashes of this road","Unavailable – no "&(B23-1)&" MMARAS record (not imputed)") -> Actual 2022 crashes of this road | K23: =IF(ISNUMBER(I23),"Yes","No – excluded") -> Yes | M23: 5. Data-quality flags (values kept as recorded): Magsaysay/R-6 crashes in 2020 = 154 (≈6% of 2019, vs 30–60% drops on other roads); MCARTHUR HIGHWAY length = 684.855 km
A24: =SOURCE_DATA!A7 -> C.P. GARCIA /KATIPUNAN AVE. / TANDANG SORA | B24: 2024 | C24: =SOURCE_DATA!K7 -> 250762 | D24: =SOURCE_DATA!U7 -> 8633 | E24: Training | F24: =SOURCE_DATA!W7 -> 43.87 | G24: =SOURCE_DATA!X7 -> 10 | H24: =SOURCE_DATA!Y7 -> 438.7 | I24: =IF(COUNTIFS($A$5:$A$144,A24,$B$5:$B$144,B24-1)=1,SUMIFS($D$5:$D$144,$A$5:$A$144,A24,$B$5:$B$144,B24-1),"N/A") -> 8119 | J24: =IF(ISNUMBER(I24),"Actual "&(B24-1)&" crashes of this road","Unavailable – no "&(B24-1)&" MMARAS record (not imputed)") -> Actual 2023 crashes of this road | K24: =IF(ISNUMBER(I24),"Yes","No – excluded") -> Yes | M24: (lanes-km 4,109) and MARCOS HIGHWAY 117.5 km are far larger than other roads and become high-leverage points for any lanes-km term; Aurora has no separate crash count.
A25: =SOURCE_DATA!A8 -> ROXAS BLVD. | B25: 2015 | C25: =SOURCE_DATA!B8 -> 173195 | D25: =SOURCE_DATA!L8 -> 1528 | E25: Training | F25: =SOURCE_DATA!W8 -> 7.6 | G25: =SOURCE_DATA!X8 -> 8 | H25: =SOURCE_DATA!Y8 -> 60.8 | I25: =IF(COUNTIFS($A$5:$A$144,A25,$B$5:$B$144,B25-1)=1,SUMIFS($D$5:$D$144,$A$5:$A$144,A25,$B$5:$B$144,B25-1),"N/A") -> N/A | J25: =IF(ISNUMBER(I25),"Actual "&(B25-1)&" crashes of this road","Unavailable – no "&(B25-1)&" MMARAS record (not imputed)") -> Unavailable – no 2014 MMARAS record (not imputed) | K25: =IF(ISNUMBER(I25),"Yes","No – excluded") -> No – excluded | M25: 6. Prev formula: =IF(COUNTIFS(Road, Year−1)=1, SUMIFS(Crashes, Road, Year−1), "N/A") → matched by BOTH road and year, never by adjacent row.
A26: =SOURCE_DATA!A8 -> ROXAS BLVD. | B26: 2016 | C26: =SOURCE_DATA!C8 -> 175185 | D26: =SOURCE_DATA!M8 -> 1877 | E26: Training | F26: =SOURCE_DATA!W8 -> 7.6 | G26: =SOURCE_DATA!X8 -> 8 | H26: =SOURCE_DATA!Y8 -> 60.8 | I26: =IF(COUNTIFS($A$5:$A$144,A26,$B$5:$B$144,B26-1)=1,SUMIFS($D$5:$D$144,$A$5:$A$144,A26,$B$5:$B$144,B26-1),"N/A") -> 1528 | J26: =IF(ISNUMBER(I26),"Actual "&(B26-1)&" crashes of this road","Unavailable – no "&(B26-1)&" MMARAS record (not imputed)") -> Actual 2015 crashes of this road | K26: =IF(ISNUMBER(I26),"Yes","No – excluded") -> Yes | M26: Colour legend: Blue = typed input | Green = link to SOURCE_DATA | Black = formula | Green fill = result | Orange fill = EDSA test rows.
A27: =SOURCE_DATA!A8 -> ROXAS BLVD. | B27: 2017 | C27: =SOURCE_DATA!D8 -> 191120 | D27: =SOURCE_DATA!N8 -> 2365 | E27: Training | F27: =SOURCE_DATA!W8 -> 7.6 | G27: =SOURCE_DATA!X8 -> 8 | H27: =SOURCE_DATA!Y8 -> 60.8 | I27: =IF(COUNTIFS($A$5:$A$144,A27,$B$5:$B$144,B27-1)=1,SUMIFS($D$5:$D$144,$A$5:$A$144,A27,$B$5:$B$144,B27-1),"N/A") -> 1877 | J27: =IF(ISNUMBER(I27),"Actual "&(B27-1)&" crashes of this road","Unavailable – no "&(B27-1)&" MMARAS record (not imputed)") -> Actual 2016 crashes of this road | K27: =IF(ISNUMBER(I27),"Yes","No – excluded") -> Yes
A28: =SOURCE_DATA!A8 -> ROXAS BLVD. | B28: 2018 | C28: =SOURCE_DATA!E8 -> 203487 | D28: =SOURCE_DATA!O8 -> 2540 | E28: Training | F28: =SOURCE_DATA!W8 -> 7.6 | G28: =SOURCE_DATA!X8 -> 8 | H28: =SOURCE_DATA!Y8 -> 60.8 | I28: =IF(COUNTIFS($A$5:$A$144,A28,$B$5:$B$144,B28-1)=1,SUMIFS($D$5:$D$144,$A$5:$A$144,A28,$B$5:$B$144,B28-1),"N/A") -> 2365 | J28: =IF(ISNUMBER(I28),"Actual "&(B28-1)&" crashes of this road","Unavailable – no "&(B28-1)&" MMARAS record (not imputed)") -> Actual 2017 crashes of this road | K28: =IF(ISNUMBER(I28),"Yes","No – excluded") -> Yes
A29: =SOURCE_DATA!A8 -> ROXAS BLVD. | B29: 2019 | C29: =SOURCE_DATA!F8 -> 203582 | D29: =SOURCE_DATA!P8 -> 2737 | E29: Training | F29: =SOURCE_DATA!W8 -> 7.6 | G29: =SOURCE_DATA!X8 -> 8 | H29: =SOURCE_DATA!Y8 -> 60.8 | I29: =IF(COUNTIFS($A$5:$A$144,A29,$B$5:$B$144,B29-1)=1,SUMIFS($D$5:$D$144,$A$5:$A$144,A29,$B$5:$B$144,B29-1),"N/A") -> 2540 | J29: =IF(ISNUMBER(I29),"Actual "&(B29-1)&" crashes of this road","Unavailable – no "&(B29-1)&" MMARAS record (not imputed)") -> Actual 2018 crashes of this road | K29: =IF(ISNUMBER(I29),"Yes","No – excluded") -> Yes
A30: =SOURCE_DATA!A8 -> ROXAS BLVD. | B30: 2020 | C30: =SOURCE_DATA!G8 -> 190626 | D30: =SOURCE_DATA!Q8 -> 1401 | E30: Training | F30: =SOURCE_DATA!W8 -> 7.6 | G30: =SOURCE_DATA!X8 -> 8 | H30: =SOURCE_DATA!Y8 -> 60.8 | I30: =IF(COUNTIFS($A$5:$A$144,A30,$B$5:$B$144,B30-1)=1,SUMIFS($D$5:$D$144,$A$5:$A$144,A30,$B$5:$B$144,B30-1),"N/A") -> 2737 | J30: =IF(ISNUMBER(I30),"Actual "&(B30-1)&" crashes of this road","Unavailable – no "&(B30-1)&" MMARAS record (not imputed)") -> Actual 2019 crashes of this road | K30: =IF(ISNUMBER(I30),"Yes","No – excluded") -> Yes
A31: =SOURCE_DATA!A8 -> ROXAS BLVD. | B31: 2021 | C31: =SOURCE_DATA!H8 -> 209339 | D31: =SOURCE_DATA!R8 -> 1283 | E31: Training | F31: =SOURCE_DATA!W8 -> 7.6 | G31: =SOURCE_DATA!X8 -> 8 | H31: =SOURCE_DATA!Y8 -> 60.8 | I31: =IF(COUNTIFS($A$5:$A$144,A31,$B$5:$B$144,B31-1)=1,SUMIFS($D$5:$D$144,$A$5:$A$144,A31,$B$5:$B$144,B31-1),"N/A") -> 1401 | J31: =IF(ISNUMBER(I31),"Actual "&(B31-1)&" crashes of this road","Unavailable – no "&(B31-1)&" MMARAS record (not imputed)") -> Actual 2020 crashes of this road | K31: =IF(ISNUMBER(I31),"Yes","No – excluded") -> Yes
A32: =SOURCE_DATA!A8 -> ROXAS BLVD. | B32: 2022 | C32: =SOURCE_DATA!I8 -> 186079 | D32: =SOURCE_DATA!S8 -> 1786 | E32: Training | F32: =SOURCE_DATA!W8 -> 7.6 | G32: =SOURCE_DATA!X8 -> 8 | H32: =SOURCE_DATA!Y8 -> 60.8 | I32: =IF(COUNTIFS($A$5:$A$144,A32,$B$5:$B$144,B32-1)=1,SUMIFS($D$5:$D$144,$A$5:$A$144,A32,$B$5:$B$144,B32-1),"N/A") -> 1283 | J32: =IF(ISNUMBER(I32),"Actual "&(B32-1)&" crashes of this road","Unavailable – no "&(B32-1)&" MMARAS record (not imputed)") -> Actual 2021 crashes of this road | K32: =IF(ISNUMBER(I32),"Yes","No – excluded") -> Yes
A33: =SOURCE_DATA!A8 -> ROXAS BLVD. | B33: 2023 | C33: =SOURCE_DATA!J8 -> 190184 | D33: =SOURCE_DATA!T8 -> 1817 | E33: Training | F33: =SOURCE_DATA!W8 -> 7.6 | G33: =SOURCE_DATA!X8 -> 8 | H33: =SOURCE_DATA!Y8 -> 60.8 | I33: =IF(COUNTIFS($A$5:$A$144,A33,$B$5:$B$144,B33-1)=1,SUMIFS($D$5:$D$144,$A$5:$A$144,A33,$B$5:$B$144,B33-1),"N/A") -> 1786 | J33: =IF(ISNUMBER(I33),"Actual "&(B33-1)&" crashes of this road","Unavailable – no "&(B33-1)&" MMARAS record (not imputed)") -> Actual 2022 crashes of this road | K33: =IF(ISNUMBER(I33),"Yes","No – excluded") -> Yes
A34: =SOURCE_DATA!A8 -> ROXAS BLVD. | B34: 2024 | C34: =SOURCE_DATA!K8 -> 202820 | D34: =SOURCE_DATA!U8 -> 1659 | E34: Training | F34: =SOURCE_DATA!W8 -> 7.6 | G34: =SOURCE_DATA!X8 -> 8 | H34: =SOURCE_DATA!Y8 -> 60.8 | I34: =IF(COUNTIFS($A$5:$A$144,A34,$B$5:$B$144,B34-1)=1,SUMIFS($D$5:$D$144,$A$5:$A$144,A34,$B$5:$B$144,B34-1),"N/A") -> 1817 | J34: =IF(ISNUMBER(I34),"Actual "&(B34-1)&" crashes of this road","Unavailable – no "&(B34-1)&" MMARAS record (not imputed)") -> Actual 2023 crashes of this road | K34: =IF(ISNUMBER(I34),"Yes","No – excluded") -> Yes
A35: =SOURCE_DATA!A9 -> TAFT AVE. | B35: 2015 | C35: =SOURCE_DATA!B9 -> 91185 | D35: =SOURCE_DATA!L9 -> 789 | E35: Training | F35: =SOURCE_DATA!W9 -> 7 | G35: =SOURCE_DATA!X9 -> 6 | H35: =SOURCE_DATA!Y9 -> 42 | I35: =IF(COUNTIFS($A$5:$A$144,A35,$B$5:$B$144,B35-1)=1,SUMIFS($D$5:$D$144,$A$5:$A$144,A35,$B$5:$B$144,B35-1),"N/A") -> N/A | J35: =IF(ISNUMBER(I35),"Actual "&(B35-1)&" crashes of this road","Unavailable – no "&(B35-1)&" MMARAS record (not imputed)") -> Unavailable – no 2014 MMARAS record (not imputed) | K35: =IF(ISNUMBER(I35),"Yes","No – excluded") -> No – excluded
A36: =SOURCE_DATA!A9 -> TAFT AVE. | B36: 2016 | C36: =SOURCE_DATA!C9 -> 89848 | D36: =SOURCE_DATA!M9 -> 979 | E36: Training | F36: =SOURCE_DATA!W9 -> 7 | G36: =SOURCE_DATA!X9 -> 6 | H36: =SOURCE_DATA!Y9 -> 42 | I36: =IF(COUNTIFS($A$5:$A$144,A36,$B$5:$B$144,B36-1)=1,SUMIFS($D$5:$D$144,$A$5:$A$144,A36,$B$5:$B$144,B36-1),"N/A") -> 789 | J36: =IF(ISNUMBER(I36),"Actual "&(B36-1)&" crashes of this road","Unavailable – no "&(B36-1)&" MMARAS record (not imputed)") -> Actual 2015 crashes of this road | K36: =IF(ISNUMBER(I36),"Yes","No – excluded") -> Yes
A37: =SOURCE_DATA!A9 -> TAFT AVE. | B37: 2017 | C37: =SOURCE_DATA!D9 -> 90586 | D37: =SOURCE_DATA!N9 -> 937 | E37: Training | F37: =SOURCE_DATA!W9 -> 7 | G37: =SOURCE_DATA!X9 -> 6 | H37: =SOURCE_DATA!Y9 -> 42 | I37: =IF(COUNTIFS($A$5:$A$144,A37,$B$5:$B$144,B37-1)=1,SUMIFS($D$5:$D$144,$A$5:$A$144,A37,$B$5:$B$144,B37-1),"N/A") -> 979 | J37: =IF(ISNUMBER(I37),"Actual "&(B37-1)&" crashes of this road","Unavailable – no "&(B37-1)&" MMARAS record (not imputed)") -> Actual 2016 crashes of this road | K37: =IF(ISNUMBER(I37),"Yes","No – excluded") -> Yes
A38: =SOURCE_DATA!A9 -> TAFT AVE. | B38: 2018 | C38: =SOURCE_DATA!E9 -> 91766 | D38: =SOURCE_DATA!O9 -> 930 | E38: Training | F38: =SOURCE_DATA!W9 -> 7 | G38: =SOURCE_DATA!X9 -> 6 | H38: =SOURCE_DATA!Y9 -> 42 | I38: =IF(COUNTIFS($A$5:$A$144,A38,$B$5:$B$144,B38-1)=1,SUMIFS($D$5:$D$144,$A$5:$A$144,A38,$B$5:$B$144,B38-1),"N/A") -> 937 | J38: =IF(ISNUMBER(I38),"Actual "&(B38-1)&" crashes of this road","Unavailable – no "&(B38-1)&" MMARAS record (not imputed)") -> Actual 2017 crashes of this road | K38: =IF(ISNUMBER(I38),"Yes","No – excluded") -> Yes
A39: =SOURCE_DATA!A9 -> TAFT AVE. | B39: 2019 | C39: =SOURCE_DATA!F9 -> 100065 | D39: =SOURCE_DATA!P9 -> 1101 | E39: Training | F39: =SOURCE_DATA!W9 -> 7 | G39: =SOURCE_DATA!X9 -> 6 | H39: =SOURCE_DATA!Y9 -> 42 | I39: =IF(COUNTIFS($A$5:$A$144,A39,$B$5:$B$144,B39-1)=1,SUMIFS($D$5:$D$144,$A$5:$A$144,A39,$B$5:$B$144,B39-1),"N/A") -> 930 | J39: =IF(ISNUMBER(I39),"Actual "&(B39-1)&" crashes of this road","Unavailable – no "&(B39-1)&" MMARAS record (not imputed)") -> Actual 2018 crashes of this road | K39: =IF(ISNUMBER(I39),"Yes","No – excluded") -> Yes
A40: =SOURCE_DATA!A9 -> TAFT AVE. | B40: 2020 | C40: =SOURCE_DATA!G9 -> 110916 | D40: =SOURCE_DATA!Q9 -> 502 | E40: Training | F40: =SOURCE_DATA!W9 -> 7 | G40: =SOURCE_DATA!X9 -> 6 | H40: =SOURCE_DATA!Y9 -> 42 | I40: =IF(COUNTIFS($A$5:$A$144,A40,$B$5:$B$144,B40-1)=1,SUMIFS($D$5:$D$144,$A$5:$A$144,A40,$B$5:$B$144,B40-1),"N/A") -> 1101 | J40: =IF(ISNUMBER(I40),"Actual "&(B40-1)&" crashes of this road","Unavailable – no "&(B40-1)&" MMARAS record (not imputed)") -> Actual 2019 crashes of this road | K40: =IF(ISNUMBER(I40),"Yes","No – excluded") -> Yes
A41: =SOURCE_DATA!A9 -> TAFT AVE. | B41: 2021 | C41: =SOURCE_DATA!H9 -> 114715 | D41: =SOURCE_DATA!R9 -> 395 | E41: Training | F41: =SOURCE_DATA!W9 -> 7 | G41: =SOURCE_DATA!X9 -> 6 | H41: =SOURCE_DATA!Y9 -> 42 | I41: =IF(COUNTIFS($A$5:$A$144,A41,$B$5:$B$144,B41-1)=1,SUMIFS($D$5:$D$144,$A$5:$A$144,A41,$B$5:$B$144,B41-1),"N/A") -> 502 | J41: =IF(ISNUMBER(I41),"Actual "&(B41-1)&" crashes of this road","Unavailable – no "&(B41-1)&" MMARAS record (not imputed)") -> Actual 2020 crashes of this road | K41: =IF(ISNUMBER(I41),"Yes","No – excluded") -> Yes
...

Sheet LR_CAL
A1: LR_CAL – Linear Regression (OLS): (A) original AADT-only baseline and (B) extended model with AADT, Year, Prev and Total lanes-km – trained on 117 non-EDSA observations
A2: EDSA is NOT used for any coefficient. Rows below the training block (orange) are EDSA test rows: predicted with the fitted coefficients only. Green = link to DATASETS, black = Excel formula.
A4: A. BASELINE (original model): ŷ = b₀ + b₁·AADT – every number is an ordinary Excel formula (sums of the data table). (This data is only model development)
A6: n (training observations) | B6: =COUNT($B$53:$B$169) -> 117
A7: Σ X (AADT) | B7: =SUM($B$53:$B$169) -> 19527528
A8: Σ Y (crashes) | B8: =SUM($F$53:$F$169) -> 220006
A9: Σ XY | B9: =SUMPRODUCT($B$53:$B$169,$F$53:$F$169) -> 46339058925 | C9: =SUM(H53:H169) -> 46339058925 | D9: =IF(ABS(C9-B9)<0.001,"✔ equals column H total (Excl. Edsa)","CHECK") -> ✔ equals column H total (Excl. Edsa)
A10: Σ X² | B10: =SUMSQ($B$53:$B$169) -> 3.8846445e+12 | C10: =SUM(I53:I169) -> 3.8846445e+12 | D10: =IF(ABS(C10-B10)<0.001,"✔ equals column I total (Excl. Edsa)","CHECK") -> ✔ equals column I total (Excl. Edsa)
A11: Σ Y² | B11: =SUMSQ($F$53:$F$169) -> 830967730 | C11: =SUM(J53:J169) -> 830967730 | D11: =IF(ABS(C11-B11)<0.001,"✔ equals column J total (Excl. Edsa)","CHECK") -> ✔ equals column J total (Excl. Edsa)
A12: Mean X | B12: =B7/B6 -> 166901.95
A13: Mean Y | B13: =B8/B6 -> 1880.3932
A14: Slope b₁ = (nΣXY − ΣXΣY) / (nΣX² − (ΣX)²) | B14: =(B6*B9-B7*B8)/(B6*B10-B7^2) -> 0.015380038
A15: Intercept b₀ = Ȳ − b₁X̄ | B15: =B13-B14*B12 -> -686.56525
A16: SSE = Σ(y − ŷ)² | B16: =SUM($N$53:$N$169) -> 2.6931971e+08
A17: SST = Σ(y − Ȳ)² | B17: =SUM($O$53:$O$169) -> 4.1726995e+08
A18: R² = 1 − SSE/SST | B18: =1-B16/B17 -> 0.35456721
A19: MAE = Σ|y − ŷ| / n | B19: =SUM($M$53:$M$169)/B6 -> 983.74255
A20: RMSE = √(SSE/n) | B20: =SQRT(B16/B6) -> 1517.1941
A21: Cross-check with Excel built-ins: SLOPE / INTERCEPT / RSQ | B21: =SLOPE($F$53:$F$169,$B$53:$B$169) -> 0.015380038 | C21: =INTERCEPT($F$53:$F$169,$B$53:$B$169) -> -686.56525 | D21: =RSQ($F$53:$F$169,$B$53:$B$169) -> 0.35456721 | E21: =IF(AND(ABS(B21-B14)<0.000000001,ABS(C21-B15)<0.000001,ABS(D21-B18)<0.000000001),"✔ matches","CHECK") -> ✔ matches
A23: B. EXTENDED LINEAR REGRESSION: ŷ = b₀ + b₁·AADT + b₂·Year + b₃·Prev + b₄·LaneKm (least squares on 4 predictors)
A24: Coefficient | B24: Fitted value | C24: Role of the predictor
A25: Intercept b₀ | B25: =INDEX(LINEST($F$53:$F$169,$B$53:$E$169,TRUE(),TRUE()),1,5) -> 48525.084 | C25: Baseline crash level when all predictors are 0 (no direct meaning – Year is ~2020)
A26: b₁ AADT | B26: =INDEX(LINEST($F$53:$F$169,$B$53:$E$169,TRUE(),TRUE()),1,4) -> 0.0029832332 | C26: Extra crashes per +1 vehicle/day, holding Year, Prev, LaneKm fixed
A27: b₂ Year | B27: =INDEX(LINEST($F$53:$F$169,$B$53:$E$169,TRUE(),TRUE()),1,3) -> -24.170108 | C27: Linear time trend: change in crashes per calendar year, others fixed (a straight line cannot capture the 2020 drop)
A28: b₃ Prev | B28: =INDEX(LINEST($F$53:$F$169,$B$53:$E$169,TRUE(),TRUE()),1,2) -> 0.92466481 | C28: Share of last year’s crash count carried into this year (crash history / persistence)
A29: b₄ LaneKm | B29: =INDEX(LINEST($F$53:$F$169,$B$53:$E$169,TRUE(),TRUE()),1,1) -> 0.013205236 | C29: Extra crashes per +1 lane-km (road size/capacity), others fixed. Road identity is NOT encoded here – see note 3 below
A31: SSE = Σ(y − ŷ)² | B31: =SUM($S$53:$S$169) -> 50660282
A32: SST = Σ(y − Ȳ)² | B32: =SUM($T$53:$T$169) -> 4.1726995e+08
A33: R² = 1 − SSE/SST | B33: =1-B31/B32 -> 0.87859111
A34: MAE = Σ|y − ŷ| / n | B34: =SUM($R$53:$R$169)/B6 -> 396.39209
A35: RMSE = √(SSE/n) | B35: =SQRT(B31/B6) -> 658.02269
A36: Adjusted R² = 1 − (1−R²)(n−1)/(n−k−1), k = 4 | B36: =1-(1-B33)*(B6-1)/(B6-4-1) -> 0.87425508
A37: Cross-check: R² from LINEST statistics | B37: =INDEX(LINEST($F$53:$F$169,$B$53:$E$169,TRUE(),TRUE()),3,1) -> 0.87859111 | C37: =IF(ABS(B37-B33)<0.000000001,"✔ matches","CHECK") -> ✔ matches
A38: Cross-check: first training prediction = b₀+Σ bᵢxᵢ vs sum of contribution columns | B38: =P53-SUM(U53:Y53) -> 1.4779289e-12
A40: HOW THE MODEL HANDLES MULTIPLE PREDICTORS AND WHAT IS EXCEL vs FITTED
A41: 1. Least squares picks b₀…b₄ to minimise SSE over the 117 training rows; each coefficient is the effect of that predictor holding the others fixed.
A42: 2. Fitted by Excel LINEST (matrix least squares). The same estimator is derived step-by-step with matrices on sheet MLR_CALC (with road effects).
A43: 3. Road identity is encoded on MLR_CALC. Here lanes-km (a road-level constant) represents road characteristics; lanes-km and 13 road cannot be
A44: estimated together because lanes-km is an exact linear combination of the road indicators (rank 16 of 17 – proved on MLR_CALC).
A45: 4. Direct Excel formulas: sums, means, baseline slope/intercept, predictions ŷ = b₀+Σbᵢxᵢ, residuals, |residual|, residual², SSE, SST, R², MAE, RMSE, contributions.
...

Sheet RF_CAL
A1: RF_CAL – Random Forest Regression (10 bootstrap trees): (A) original AADT-only configuration and (B) extended predictors – trained on 117 non-EDSA observations
A2: Split features/thresholds and bootstrap draw counts (yellow) were produced by the fitted scikit-learn model. Leaf values, tree predictions, forest averages and all errors are live Excel formulas. EDSA is never used to fit.
A4: A. MODEL CONFIGURATION (scikit-learn RandomForestRegressor – same hyper-parameters as the original AADT-only model)
A5: Library / version | B5: scikit-learn 1.8.0
A6: n_estimators (trees) | B6: 10
A7: max_depth | B7: 3
A8: min_samples_leaf | B8: 3
A9: bootstrap | B9: TRUE (117 draws with replacement per tree)
A10: max_features | B10: 1.0 (all predictors considered at every split)
A11: criterion | B11: squared_error
A12: random_state (master seed) | B12: 42
A13: Training observations | B13: =COUNT($T$90:$T$206) -> 117
A14: A. Baseline predictors | B14: AADT only
A15: B. Extended predictors (17 columns) | B15: AADT, Year, Prev, LaneKm + 13 one-hot road indicators (columns G–S)
A16: Categorical encoding of Road | B16: One-hot: one 0/1 column per training road. EDSA is not a training road → all 13 indicators = 0 (road identity unknown to the forest).
A18: B. HOW THE FOREST IS FITTED AND HOW IT PREDICTS (no single linear equation exists)
A19: 1. Bootstrap: for each tree, 117 rows are drawn WITH replacement from the 117 training rows (draw counts in the yellow count columns of each block).
A20: 2. Tree growth: at every node the algorithm tries every predictor and split point and keeps the one that most reduces squared error; stops at depth 3 or when a leaf would
A21: have fewer than 3 samples. The chosen predictor/threshold of every node are in the yellow split tables at the bottom of this sheet (fitted by Python).
A22: 3. Leaf value = bootstrap-weighted mean of Y of the training rows falling in that leaf – recomputed here with SUMPRODUCT formulas (white cells in the leaf-value tables).
A23: 4. Tree prediction = value of the leaf the row falls into (leaf found with a nested IF built from the split table). Forest prediction = average of the 10 trees.
A24: 5. Model-generated: the split choices and bootstrap draws. Ordinary Excel: leaf means, tree predictions, averages, residuals, SSE, SST, R², MAE, RMSE.
A25: 6. Trees cannot extrapolate: if EDSA’s Prev, AADT or Year lie above the highest training split, it receives the value of the top leaf (see EDSA_TEST_ROAD).
A27: C. TRAINING METRICS (117 training rows; formulas)
A28: Metric | B28: A: AADT only | C28: B: Extended
A29: SSE = Σ(y − ŷ)² | B29: =SUM($BB$90:$BB$206) -> 1.7288248e+08 | C29: =SUM($CL$90:$CL$206) -> 26417619
A30: SST = Σ(y − Ȳ)² | B30: =SUM($BC$90:$BC$206) -> 4.1726995e+08 | C30: =SUM($CM$90:$CM$206) -> 4.1726995e+08
A31: R² = 1 − SSE/SST | B31: =1-B29/B30 -> 0.58568193 | C31: =1-C29/C30 -> 0.93668938
A32: MAE = Σ|y − ŷ|/n | B32: =SUM($BA$90:$BA$206)/$B$13 -> 824.45577 | C32: =SUM($CK$90:$CK$206)/$B$13 -> 340.64423
A33: RMSE = √(SSE/n) | B33: =SQRT(B29/$B$13) -> 1215.5772 | C33: =SQRT(C29/$B$13) -> 475.17535
A34: Training metrics of tree models are optimistic (they fit the training roads closely); judge them on EDSA_TEST_ROAD.
A36: D. WORKED EXAMPLE – trace one observation through the 10 trees (change the blue observation number: 1–117 training, 118–126 EDSA test; default 122 = EDSA 2020)
A37: Observation # | B37: 122
A38: Road | B38: =INDEX($A$90:$A$215,$B$37) -> EDSA
A39: Dataset | B39: =INDEX($B$90:$B$215,$B$37) -> EDSA Test
A40: AADT | B40: =INDEX($C$90:$C$215,$B$37) -> 328114
A41: Year | B41: =INDEX($D$90:$D$215,$B$37) -> 2020
A42: Prev | B42: =INDEX($E$90:$E$215,$B$37) -> 17382
A43: LaneKm | B43: =INDEX($F$90:$F$215,$B$37) -> 285.6
A44: Actual crashes | B44: =INDEX($T$90:$T$215,$B$37) -> 7319
...

Sheet MLR_CALC
A1: MLR_CALC – Multiple Linear Regression with road effects: ŷ = β₀ + β₁·AADT + β₂·Year + β₃·Prev + Road effects (117 training observations)
A2: Coefficients are computed in Excel with the normal equations β = (ZᵀZ)⁻¹Zᵀy on a STANDARDISED design matrix Z, then converted back to original units. EDSA is never used.
A4: A. SCALING (numerical stability): AADT, Year and Prev are standardised z = (x − mean)/sd using TRAINING rows only; road are 0/1
A5: Variable | B5: Mean (training) | C5: Std. dev. (training)
A6: AADT | B6: =AVERAGE($C$119:$C$235) -> 166901.95 | C6: =STDEV($C$119:$C$235) -> 73429.646
A7: Year | B7: =AVERAGE($B$119:$B$235) -> 2020 | C7: =STDEV($B$119:$B$235) -> 2.5930943
A8: Prev | B8: =AVERAGE($D$119:$D$235) -> 1811 | C8: =STDEV($D$119:$D$235) -> 1781.6738
A9: n (training observations) | B9: =COUNT($F$119:$F$235) -> 117
A10: Number of training roads (for EDSA road encoding) | B10: =DATASETS!N6 -> 13
A11: Mean Y (training) | B11: =AVERAGE($F$119:$F$235) -> 1880.3932
A13: B. DESIGN MATRIX Z (columns G–V of the data table below): 16 columns = intercept | z(AADT) | z(Year) | z(Prev) | 12 road dummies (reference road = PRES. QUIRINO AVE.)
A14: ZᵀZ (16×16, array formula MMULT(TRANSPOSE(Z),Z)) | B14: Intercept | C14: z AADT | D14: z Year | E14: z Prev | F14: Road: C.P. GARCIA /KATIPUNAN AVE. / TANDANG SORA | G14: Road: ROXAS BLVD. | H14: Road: TAFT AVE. | I14: Road: SSH | J14: Road: ORTIGAS AVE. | K14: Road: R-6 MAGSAYSAY / AURORA BLVD. | L14: Road: QUEZON AVE. | M14: Road: COMMONWEALTH AVE. | N14: Road: RIZAL AVE. | O14: Road: DEL PAN | P14: Road: MARCOS HIGHWAY | Q14: Road: MCARTHUR HIGHWAY
A15: Intercept | B15: {=MMULT(TRANSPOSE($G$119:$V$235),$G$119:$V$235)} -> 117 | C15: -8.7707619e-15 | D15: 0 | E15: -8.8817842e-16 | F15: 9 | G15: 9 | H15: 9 | I15: 9 | J15: 9 | K15: 9 | L15: 9 | M15: 9 | N15: 9 | O15: 9 | P15: 9 | Q15: 9
A16: z AADT | B16: -8.7707619e-15 | C16: 116 | D16: 33.767873 | E16: 65.559867 | F16: 6.9804425 | G16: 3.4087652 | H16: -6.2143508 | I16: -1.4495042 | J16: 0.4588259 | K16: -6.0647858 | L16: 9.6240478 | M16: 18.483194 | N16: -9.0271657 | O16: -8.9314278 | P16: 5.5707667 | Q16: -7.7186206
A17: z Year | B17: 0 | C17: 33.767873 | D17: 116 | E17: -1.368384 | F17: 0 | G17: 0 | H17: 0 | I17: 0 | J17: 0 | K17: 0 | L17: 0 | M17: 0 | N17: 0 | O17: 0 | P17: 0 | Q17: 0
A18: z Prev | B18: -8.8817842e-16 | C18: 65.559867 | D18: -1.368384 | E18: 116 | F18: 24.326563 | G18: 0.58091443 | H18: -5.3550769 | I18: -4.2836125 | J18: 0.80598369 | K18: -1.130959 | L18: 0.92721801 | M18: 11.63232 | N18: -7.2381377 | O18: -4.4952113 | P18: -4.4149497 | Q18: -6.3788333
A19: Road: C.P. GARCIA /KATIPUNAN AVE. / TANDANG SORA | B19: 9 | C19: 6.9804425 | D19: 0 | E19: 24.326563 | F19: 9 | G19: 0 | H19: 0 | I19: 0 | J19: 0 | K19: 0 | L19: 0 | M19: 0 | N19: 0 | O19: 0 | P19: 0 | Q19: 0
A20: Road: ROXAS BLVD. | B20: 9 | C20: 3.4087652 | D20: 0 | E20: 0.58091443 | F20: 0 | G20: 9 | H20: 0 | I20: 0 | J20: 0 | K20: 0 | L20: 0 | M20: 0 | N20: 0 | O20: 0 | P20: 0 | Q20: 0
A21: Road: TAFT AVE. | B21: 9 | C21: -6.2143508 | D21: 0 | E21: -5.3550769 | F21: 0 | G21: 0 | H21: 9 | I21: 0 | J21: 0 | K21: 0 | L21: 0 | M21: 0 | N21: 0 | O21: 0 | P21: 0 | Q21: 0
A22: Road: SSH | B22: 9 | C22: -1.4495042 | D22: 0 | E22: -4.2836125 | F22: 0 | G22: 0 | H22: 0 | I22: 9 | J22: 0 | K22: 0 | L22: 0 | M22: 0 | N22: 0 | O22: 0 | P22: 0 | Q22: 0
A23: Road: ORTIGAS AVE. | B23: 9 | C23: 0.4588259 | D23: 0 | E23: 0.80598369 | F23: 0 | G23: 0 | H23: 0 | I23: 0 | J23: 9 | K23: 0 | L23: 0 | M23: 0 | N23: 0 | O23: 0 | P23: 0 | Q23: 0
A24: Road: R-6 MAGSAYSAY / AURORA BLVD. | B24: 9 | C24: -6.0647858 | D24: 0 | E24: -1.130959 | F24: 0 | G24: 0 | H24: 0 | I24: 0 | J24: 0 | K24: 9 | L24: 0 | M24: 0 | N24: 0 | O24: 0 | P24: 0 | Q24: 0
A25: Road: QUEZON AVE. | B25: 9 | C25: 9.6240478 | D25: 0 | E25: 0.92721801 | F25: 0 | G25: 0 | H25: 0 | I25: 0 | J25: 0 | K25: 0 | L25: 9 | M25: 0 | N25: 0 | O25: 0 | P25: 0 | Q25: 0
A26: Road: COMMONWEALTH AVE. | B26: 9 | C26: 18.483194 | D26: 0 | E26: 11.63232 | F26: 0 | G26: 0 | H26: 0 | I26: 0 | J26: 0 | K26: 0 | L26: 0 | M26: 9 | N26: 0 | O26: 0 | P26: 0 | Q26: 0
A27: Road: RIZAL AVE. | B27: 9 | C27: -9.0271657 | D27: 0 | E27: -7.2381377 | F27: 0 | G27: 0 | H27: 0 | I27: 0 | J27: 0 | K27: 0 | L27: 0 | M27: 0 | N27: 9 | O27: 0 | P27: 0 | Q27: 0
... A30: Road: MCARTHUR HIGHWAY | B30: 9 | C30: -7.7186206 | D30: 0 | E30: -6.3788333 | F30: 0 | G30: 0 | H30: 0 | I30: 0 | J30: 0 | K30: 0 | L30: 0 | M30: 0 | N30: 0 | O30: 0 | P30: 0 | Q30: 9
A32: (ZᵀZ)⁻¹ (array formula MINVERSE) | B32: Intercept | C32: z AADT | D32: z Year | E32: z Prev | F32: Road: C.P. GARCIA /KATIPUNAN AVE. / TANDANG SORA | G32: Road: ROXAS BLVD. | H32: Road: TAFT AVE. | I32: Road: SSH | J32: Road: ORTIGAS AVE. | K32: Road: R-6 MAGSAYSAY / AURORA BLVD. | L32: Road: QUEZON AVE. | M32: Road: COMMONWEALTH AVE. | N32: Road: RIZAL AVE. | O32: Road: DEL PAN | P32: Road: MARCOS HIGHWAY | Q32: Road: MCARTHUR HIGHWAY
A33: Intercept | B33: {=MINVERSE(B15:Q30)} -> 0.16631929 | C33: 0.050704257 | D33: -0.014197694 | E33: 0.047678428 | F33: -0.33451823 | G33: -0.18860107 | H33: -0.10293977 | I33: -0.13546019 | J33: -0.17317401 | K33: -0.12616009 | L33: -0.22545135 | M33: -0.33207345 | N33: -0.07711721 | O33: -0.092187515 | P33: -0.17431526 | Q33: -0.089041553
A34: z AADT | B34: 0.050704257 | C34: 0.085749798 | D34: -0.024920997 | E34: 0.0034731682 | F34: -0.12660001 | G34: -0.083406318 | H34: 0.010571121 | I34: -0.035240658 | J34: -0.055386873 | K34: 0.0075159838 | L34: -0.14275765 | M34: -0.23129661 | N34: 0.03809762 | O34: 0.036126937 | P34: -0.1020774 | Q34: 0.025298511
A35: z Year | B35: -0.014197694 | C35: -0.024920997 | D35: 0.015874826 | E35: -3.5983664e-05 | F35: 0.033623799 | G35: 0.023638886 | H35: -0.0030312517 | I35: 0.010166891 | J35: 0.015471405 | K35: -0.0026002176 | L35: 0.040850386 | M35: 0.065424162 | N35: -0.010827464 | O35: -0.010551399 | P35: 0.029605493 | Q35: -0.0072006674
A36: z Prev | B36: 0.047678428 | C36: 0.0034731682 | D36: -3.5983664e-05 | E36: 0.082657641 | F36: -0.27379183 | G36: -0.05432912 | H36: 0.0039017397 | I36: -0.0077775751 | J36: -0.055257794 | K36: -0.034951047 | L36: -0.05990816 | M36: -0.16164458 | N36: 0.0222816 | O36: -0.0029468823 | P36: -0.0092805262 | Q36: 0.013884615
A37: Road: C.P. GARCIA /KATIPUNAN AVE. / TANDANG SORA | B37: -0.33451823 | C37: -0.12660001 | D37: 0.033623799 | E37: -0.27379183 | F37: 1.2838669 | G37: 0.40014038 | H37: 0.084194549 | I37: 0.18381542 | J37: 0.36549147 | K37: 0.21480165 | L37: 0.49810371 | M37: 0.94838567 | N37: -0.012657568 | O37: 0.072132571 | P37: 0.27857179 | Q37: 0.031890468
A38: Road: ROXAS BLVD. | B38: -0.18860107 | C38: -0.083406318 | D38: 0.023638886 | E38: -0.05432912 | F38: 0.40014038 | G38: 0.3348092 | H38: 0.098684102 | I38: 0.14930966 | J38: 0.19771856 | K38: 0.12556935 | L38: 0.28338789 | M38: 0.43011095 | N38: 0.061249483 | O38: 0.078694586 | P38: 0.21357627 | Q38: 0.078563502
A39: Road: TAFT AVE. | B39: -0.10293977 | C39: 0.010571121 | D39: -0.0030312517 | E39: 0.0039017397 | F39: 0.084194549 | G39: 0.098684102 | H39: 0.22367164 | I39: 0.10649938 | J39: 0.10205144 | K39: 0.11055358 | L39: 0.091233692 | M39: 0.076187066 | N39: 0.11668073 | O39: 0.11537915 | P39: 0.098310522 | Q39: 0.11477122
A40: Road: SSH | B40: -0.13546019 | C40: -0.035240658 | D40: 0.010166891 | E40: -0.0077775751 | F40: 0.18381542 | G40: 0.14930966 | H40: 0.10649938 | I40: 0.23719379 | J40: 0.13795329 | K40: 0.11073539 | L40: 0.17394567 | M40: 0.21788588 | N40: 0.093858144 | O40: 0.096603386 | P40: 0.15345795 | Q40: 0.09972451
A41: Road: ORTIGAS AVE. | B41: -0.17317401 | C41: -0.055386873 | D41: 0.015471405 | E41: -0.055257794 | F41: 0.36549147 | G41: 0.19771856 | H41: 0.10205144 | I41: 0.13795329 | J41: 0.29205732 | K41: 0.12890692 | L41: 0.23809423 | M41: 0.35834098 | N41: 0.073179568 | O41: 0.090609644 | P41: 0.18035034 | Q41: 0.086508399
A42: Road: R-6 MAGSAYSAY / AURORA BLVD. | B42: -0.12616009 | C42: 0.0075159838 | D42: -0.0026002176 | E42: -0.034951047 | F42: 0.21480165 | G42: 0.12556935 | H42: 0.11055358 | I42: 0.11073539 | J42: 0.12890692 | K42: 0.23794394 | L42: 0.12172377 | M42: 0.15589814 | N42: 0.10558982 | O42: 0.11616188 | P42: 0.10436266 | Q42: 0.10783411
A43: Road: QUEZON AVE. | B43: -0.22545135 | C43: -0.14275765 | D43: 0.040850386 | E43: -0.05990816 | F43: 0.49810371 | G43: 0.28338789 | H43: 0.091233692 | I43: 0.17394567 | J43: 0.23809423 | K43: 0.12172377 | L43: 0.49539072 | M43: 0.59606116 | N43: 0.034082408 | O43: 0.053859185 | P43: 0.28442669 | Q43: 0.060558426
A44: Road: COMMONWEALTH AVE. | B44: -0.33207345 | C44: -0.23129661 | D44: 0.065424162 | E44: -0.16164458 | F44: 0.94838567 | G44: 0.43011095 | H44: 0.076187066 | I44: 0.21788588 | J44: 0.35834098 | K44: 0.15589814 | L44: 0.59606116 | M44: 1.1271181 | N44: -0.029921949 | O44: 0.021802834 | P44: 0.39594531 | Q44: 0.01914071
A45: Road: RIZAL AVE. | B45: -0.07711721 | C45: 0.03809762 | D45: -0.010827464 | E45: 0.0222816 | F45: -0.012657568 | G45: 0.061249483 | H45: 0.11668073 | I45: 0.093858144 | J45: 0.073179568 | K45: 0.10558982 | L45: 0.034082408 | M45: -0.029921949 | N45: 0.24436063 | O45: 0.1260535 | P45: 0.064466009 | Q45: 0.12558295
...

Sheet EDSA_TEST_ROAD
A1: EDSA_TEST_ROAD – Independent out-of-sample test of all models on EDSA, 2016–2024 (9 test years with a known previous-year crash count)
A2: All models were fitted on the 13 non-EDSA roads only. Residual = Actual − Predicted (positive = under-prediction). Predictions are NOT rounded; only the display format is. Prev for each year is the actual EDSA count of the previous year.
A5: EDSA test data (DATASETS) | G5: LR – AADT only (baseline) | K5: LR – extended | O5: MLR – extended with road effects | S5: RF – AADT only (baseline) | W5: RF – extended | AA5: ACCURACY PER YEAR = 1 − |Actual − Predicted| / Actual
A6: Year | B6: EDSA AADT (veh/day) | C6: Road length (km) | D6: Total lanes-km | E6: Actual EDSA crashes | F6: Prev (actual crashes Year−1) | G6: Predicted | H6: Residual | I6: Absolute error | J6: Squared error | K6: Predicted | L6: Residual | M6: Absolute error | N6: Squared error | O6: Predicted | P6: Residual | Q6: Absolute error | R6: Squared error | S6: Predicted | T6: Residual | U6: Absolute error | V6: Squared error | W6: Predicted | X6: Residual | Y6: Absolute error | Z6: Squared error | AA6: Accuracy 1−|e|/y: LR – AADT only (baseline) | AB6: Accuracy 1−|e|/y: LR – extended | AC6: Accuracy 1−|e|/y: MLR – extended with road effects | AD6: Accuracy 1−|e|/y: RF – AADT only (baseline) | AE6: Accuracy 1−|e|/y: RF – extended
A7: =DATASETS!B136 -> 2016 | B7: =DATASETS!C136 -> 364781 | C7: =DATASETS!F136 -> 23.8 | D7: =DATASETS!H136 -> 285.6 | E7: =DATASETS!D136 -> 13354 | F7: =DATASETS!I136 -> 9801 | G7: =LR_CAL!K170 -> 4923.7805 | H7: =$E7-G7 -> 8430.2195 | I7: =ABS(H7) -> 8430.2195 | J7: =H7^2 -> 71068601 | K7: =LR_CAL!P170 -> 9952.7833 | L7: =$E7-K7 -> 3401.2167 | M7: =ABS(L7) -> 3401.2167 | N7: =L7^2 -> 11568275 | O7: =MLR_CALC!W236 -> 5716.597 | P7: =$E7-O7 -> 7637.403 | Q7: =ABS(P7) -> 7637.403 | R7: =P7^2 -> 58329925 | S7: =RF_CAL!AY207 -> 3765.4914 | T7: =$E7-S7 -> 9588.5086 | U7: =ABS(T7) -> 9588.5086 | V7: =T7^2 -> 91939497 | W7: =RF_CAL!CI207 -> 6959.8437 | X7: =$E7-W7 -> 6394.1563 | Y7: =ABS(X7) -> 6394.1563 | Z7: =X7^2 -> 40885235 | AA7: =1-I7/$E7 -> 0.36871203 | AB7: =1-M7/$E7 -> 0.74530353 | AC7: =1-Q7/$E7 -> 0.42808125 | AD7: =1-U7/$E7 -> 0.2819748 | AE7: =1-Y7/$E7 -> 0.52118044
A8: =DATASETS!B137 -> 2017 | B8: =DATASETS!C137 -> 367728 | C8: =DATASETS!F137 -> 23.8 | D8: =DATASETS!H137 -> 285.6 | E8: =DATASETS!D137 -> 12635 | F8: =DATASETS!I137 -> 13354 | G8: =LR_CAL!K171 -> 4969.1054 | H8: =$E8-G8 -> 7665.8946 | I8: =ABS(H8) -> 7665.8946 | J8: =H8^2 -> 58765939 | K8: =LR_CAL!P171 -> 13222.739 | L8: =$E8-K8 -> -587.73886 | M8: =ABS(L8) -> 587.73886 | N8: =L8^2 -> 345436.97 | O8: =MLR_CALC!W237 -> 6810.1947 | P8: =$E8-O8 -> 5824.8053 | Q8: =ABS(P8) -> 5824.8053 | R8: =P8^2 -> 33928357 | S8: =RF_CAL!AY208 -> 3765.4914 | T8: =$E8-S8 -> 8869.5086 | U8: =ABS(T8) -> 8869.5086 | V8: =T8^2 -> 78668182 | W8: =RF_CAL!CI208 -> 6959.8437 | X8: =$E8-W8 -> 5675.1563 | Y8: =ABS(X8) -> 5675.1563 | Z8: =X8^2 -> 32207400 | AA8: =1-I8/$E8 -> 0.393281 | AB8: =1-M8/$E8 -> 0.95348327 | AC8: =1-Q8/$E8 -> 0.53899444 | AD8: =1-U8/$E8 -> 0.29802069 | AE8: =1-Y8/$E8 -> 0.55083844
A9: =DATASETS!B138 -> 2018 | B9: =DATASETS!C138 -> 383828 | C9: =DATASETS!F138 -> 23.8 | D9: =DATASETS!H138 -> 285.6 | E9: =DATASETS!D138 -> 17276 | F9: =DATASETS!I138 -> 12635 | G9: =LR_CAL!K172 -> 5216.7241 | H9: =$E9-G9 -> 12059.276 | I9: =ABS(H9) -> 12059.276 | J9: =H9^2 -> 1.4542614e+08 | K9: =LR_CAL!P172 -> 12581.765 | L9: =$E9-K9 -> 4694.2352 | M9: =ABS(L9) -> 4694.2352 | N9: =L9^2 -> 22035844 | O9: =MLR_CALC!W238 -> 6621.1753 | P9: =$E9-O9 -> 10654.825 | Q9: =ABS(P9) -> 10654.825 | R9: =P9^2 -> 1.1352529e+08 | S9: =RF_CAL!AY209 -> 3765.4914 | T9: =$E9-S9 -> 13510.509 | U9: =ABS(T9) -> 13510.509 | V9: =T9^2 -> 1.8253384e+08 | W9: =RF_CAL!CI209 -> 6959.8437 | X9: =$E9-W9 -> 10316.156 | Y9: =ABS(X9) -> 10316.156 | Z9: =X9^2 -> 1.0642308e+08 | AA9: =1-I9/$E9 -> 0.30196365 | AB9: =1-M9/$E9 -> 0.72827997 | AC9: =1-Q9/$E9 -> 0.38325858 | AD9: =1-U9/$E9 -> 0.21796084 | AE9: =1-Y9/$E9 -> 0.40286198
A10: =DATASETS!B139 -> 2019 | B10: =DATASETS!C139 -> 405882 | C10: =DATASETS!F139 -> 23.8 | D10: =DATASETS!H139 -> 285.6 | E10: =DATASETS!D139 -> 17382 | F10: =DATASETS!I139 -> 17276 | G10: =LR_CAL!K173 -> 5555.9154 | H10: =$E10-G10 -> 11826.085 | I10: =ABS(H10) -> 11826.085 | J10: =H10^2 -> 1.3985628e+08 | K10: =LR_CAL!P173 -> 16914.756 | L10: =$E10-K10 -> 467.2437 | M10: =ABS(L10) -> 467.2437 | N10: =L10^2 -> 218316.67 | O10: =MLR_CALC!W239 -> 8166.2026 | P10: =$E10-O10 -> 9215.7974 | Q10: =ABS(P10) -> 9215.7974 | R10: =P10^2 -> 84930921 | S10: =RF_CAL!AY210 -> 3765.4914 | T10: =$E10-S10 -> 13616.509 | U10: =ABS(T10) -> 13616.509 | V10: =T10^2 -> 1.8540931e+08 | W10: =RF_CAL!CI210 -> 6959.8437 | X10: =$E10-W10 -> 10422.156 | Y10: =ABS(X10) -> 10422.156 | Z10: =X10^2 -> 1.0862134e+08 | AA10: =1-I10/$E10 -> 0.31963614 | AB10: =1-M10/$E10 -> 0.97311911 | AC10: =1-Q10/$E10 -> 0.469808 | AD10: =1-U10/$E10 -> 0.21663166 | AE10: =1-Y10/$E10 -> 0.40040523
A11: =DATASETS!B140 -> 2020 | B11: =DATASETS!C140 -> 328114 | C11: =DATASETS!F140 -> 23.8 | D11: =DATASETS!H140 -> 285.6 | E11: =DATASETS!D140 -> 7319 | F11: =DATASETS!I140 -> 17382 | G11: =LR_CAL!K174 -> 4359.8406 | H11: =$E11-G11 -> 2959.1594 | I11: =ABS(H11) -> 2959.1594 | J11: =H11^2 -> 8756624.3 | K11: =LR_CAL!P174 -> 16756.601 | L11: =$E11-K11 -> -9437.6006 | M11: =ABS(L11) -> 9437.6006 | N11: =L11^2 -> 89068305 | O11: =MLR_CALC!W240 -> 7717.4602 | P11: =$E11-O11 -> -398.46024 | Q11: =ABS(P11) -> 398.46024 | R11: =P11^2 -> 158770.56 | S11: =RF_CAL!AY211 -> 3765.4914 | T11: =$E11-S11 -> 3553.5086 | U11: =ABS(T11) -> 3553.5086 | V11: =T11^2 -> 12627423 | W11: =RF_CAL!CI211 -> 6854.5937 | X11: =$E11-W11 -> 464.40635 | Y11: =ABS(X11) -> 464.40635 | Z11: =X11^2 -> 215673.26 | AA11: =1-I11/$E11 -> 0.59568802 | AB11: =1-M11/$E11 -> -0.28946585 | AC11: =1-Q11/$E11 -> 0.9455581 | AD11: =1-U11/$E11 -> 0.51448168 | AE11: =1-Y11/$E11 -> 0.93654784
A12: =DATASETS!B141 -> 2021 | B12: =DATASETS!C141 -> 372271 | C12: =DATASETS!F141 -> 23.8 | D12: =DATASETS!H141 -> 285.6 | E12: =DATASETS!D141 -> 6523 | F12: =DATASETS!I141 -> 7319 | G12: =LR_CAL!K175 -> 5038.977 | H12: =$E12-G12 -> 1484.023 | I12: =ABS(H12) -> 1484.023 | J12: =H12^2 -> 2202324.4 | K12: =LR_CAL!P175 -> 7559.2591 | L12: =$E12-K12 -> -1036.2591 | M12: =ABS(L12) -> 1036.2591 | N12: =L12^2 -> 1073833 | O12: =MLR_CALC!W241 -> 4719.0595 | P12: =$E12-O12 -> 1803.9405 | Q12: =ABS(P12) -> 1803.9405 | R12: =P12^2 -> 3254201.4 | S12: =RF_CAL!AY212 -> 3765.4914 | T12: =$E12-S12 -> 2757.5086 | U12: =ABS(T12) -> 2757.5086 | V12: =T12^2 -> 7603853.5 | W12: =RF_CAL!CI212 -> 6854.5937 | X12: =$E12-W12 -> -331.59365 | Y12: =ABS(X12) -> 331.59365 | Z12: =X12^2 -> 109954.35 | AA12: =1-I12/$E12 -> 0.77249378 | AB12: =1-M12/$E12 -> 0.84113765 | AC12: =1-Q12/$E12 -> 0.72344925 | AD12: =1-U12/$E12 -> 0.57726375 | AE12: =1-Y12/$E12 -> 0.94916547
A13: =DATASETS!B142 -> 2022 | B13: =DATASETS!C142 -> 385096 | C13: =DATASETS!F142 -> 23.8 | D13: =DATASETS!H142 -> 285.6 | E13: =DATASETS!D142 -> 8009 | F13: =DATASETS!I142 -> 6523 | G13: =LR_CAL!K176 -> 5236.2259 | H13: =$E13-G13 -> 2772.7741 | I13: =ABS(H13) -> 2772.7741 | J13: =H13^2 -> 7688276 | K13: =LR_CAL!P176 -> 6837.3158 | L13: =$E13-K13 -> 1171.6842 | M13: =ABS(L13) -> 1171.6842 | N13: =L13^2 -> 1372843.9 | O13: =MLR_CALC!W242 -> 4487.4086 | P13: =$E13-O13 -> 3521.5914 | Q13: =ABS(P13) -> 3521.5914 | R13: =P13^2 -> 12401606 | S13: =RF_CAL!AY213 -> 3765.4914 | T13: =$E13-S13 -> 4243.5086 | U13: =ABS(T13) -> 4243.5086 | V13: =T13^2 -> 18007365 | W13: =RF_CAL!CI213 -> 6854.5937 | X13: =$E13-W13 -> 1154.4063 | Y13: =ABS(X13) -> 1154.4063 | Z13: =X13^2 -> 1332654 | AA13: =1-I13/$E13 -> 0.65379273 | AB13: =1-M13/$E13 -> 0.85370406 | AC13: =1-Q13/$E13 -> 0.56029574 | AD13: =1-U13/$E13 -> 0.4701575 | AE13: =1-Y13/$E13 -> 0.85586136
A14: =DATASETS!B143 -> 2023 | B14: =DATASETS!C143 -> 407342 | C14: =DATASETS!F143 -> 23.8 | D14: =DATASETS!H143 -> 285.6 | E14: =DATASETS!D143 -> 8727 | F14: =DATASETS!I143 -> 8009 | G14: =LR_CAL!K177 -> 5578.3703 | H14: =$E14-G14 -> 3148.6297 | I14: =ABS(H14) -> 3148.6297 | J14: =H14^2 -> 9913869.1 | K14: =LR_CAL!P177 -> 8253.5626 | L14: =$E14-K14 -> 473.43739 | M14: =ABS(L14) -> 473.43739 | N14: =L14^2 -> 224142.97 | O14: =MLR_CALC!W243 -> 5032.2809 | P14: =$E14-O14 -> 3694.7191 | Q14: =ABS(P14) -> 3694.7191 | R14: =P14^2 -> 13650949 | S14: =RF_CAL!AY214 -> 3765.4914 | T14: =$E14-S14 -> 4961.5086 | U14: =ABS(T14) -> 4961.5086 | V14: =T14^2 -> 24616567 | W14: =RF_CAL!CI214 -> 6854.5937 | X14: =$E14-W14 -> 1872.4063 | Y14: =ABS(X14) -> 1872.4063 | Z14: =X14^2 -> 3505905.5 | AA14: =1-I14/$E14 -> 0.63920824 | AB14: =1-M14/$E14 -> 0.94575027 | AC14: =1-Q14/$E14 -> 0.57663354 | AD14: =1-U14/$E14 -> 0.43147604 | AE14: =1-Y14/$E14 -> 0.78544673
A15: =DATASETS!B144 -> 2024 | B15: =DATASETS!C144 -> 419952 | C15: =DATASETS!F144 -> 23.8 | D15: =DATASETS!H144 -> 285.6 | E15: =DATASETS!D144 -> 8873 | F15: =DATASETS!I144 -> 8727 | G15: =LR_CAL!K178 -> 5772.3126 | H15: =$E15-G15 -> 3100.6874 | I15: =ABS(H15) -> 3100.6874 | J15: =H15^2 -> 9614262.6 | K15: =LR_CAL!P178 -> 8930.9204 | L15: =$E15-K15 -> -57.920401 | M15: =ABS(L15) -> 57.920401 | N15: =L15^2 -> 3354.7729 | O15: =MLR_CALC!W244 -> 5279.895 | P15: =$E15-O15 -> 3593.105 | Q15: =ABS(P15) -> 3593.105 | R15: =P15^2 -> 12910404 | S15: =RF_CAL!AY215 -> 3765.4914 | T15: =$E15-S15 -> 5107.5086 | U15: =ABS(T15) -> 5107.5086 | V15: =T15^2 -> 26086644 | W15: =RF_CAL!CI215 -> 6854.5937 | X15: =$E15-W15 -> 2018.4063 | Y15: =ABS(X15) -> 2018.4063 | Z15: =X15^2 -> 4073964.2 | AA15: =1-I15/$E15 -> 0.65054802 | AB15: =1-M15/$E15 -> 0.99347229 | AC15: =1-Q15/$E15 -> 0.59505184 | AD15: =1-U15/$E15 -> 0.42437636 | AE15: =1-Y15/$E15 -> 0.77252267
A16: TOTAL (Σ) | E16: =SUM(E7:E15) -> 100098 | G16: =SUM(G7:G15) -> 46651.252 | H16: =SUM(H7:H15) -> 53446.748 | I16: =SUM(I7:I15) -> 53446.748 | J16: =SUM(J7:J15) -> 4.5329231e+08 | K16: =SUM(K7:K15) -> 101009.7 | L16: =SUM(L7:L15) -> -911.70181 | M16: =SUM(M7:M15) -> 21327.336 | N16: =SUM(N7:N15) -> 1.2591035e+08 | ... Z16: =SUM(Z7:Z15) -> 2.9737521e+08 | AA16: =MEDIAN(AA7:AA15) -> 0.59568802 | AB16: =MEDIAN(AB7:AB15) -> 0.85370406 | AC16: =MEDIAN(AC7:AC15) -> 0.56029574 | AD16: =MEDIAN(AD7:AD15) -> 0.42437636 | AE16: =MEDIAN(AE7:AE15) -> 0.77252267 | AF16: Median prediction
K17: =AVERAGE(K7:K15) -> 11223.3
A18: TEST METRICS ACROSS THE 9 EDSA TEST YEARS (2016–2024) – formulas
A19: Metric | B19: LR – AADT only (baseline) | C19: LR – extended | D19: MLR – extended with road effects | E19: RF – AADT only (baseline) | F19: RF – extended
A20: n (test observations) | B20: =COUNT(H7:H15) -> 9 | C20: =COUNT(L7:L15) -> 9 | D20: =COUNT(P7:P15) -> 9 | E20: =COUNT(T7:T15) -> 9 | F20: =COUNT(X7:X15) -> 9
A21: SSE = Σ(y − ŷ)² | B21: =J16 -> 4.5329231e+08 | C21: =N16 -> 1.2591035e+08 | D21: =R16 -> 3.3309042e+08 | E21: =V16 -> 6.2749268e+08 | F21: =Z16 -> 2.9737521e+08
A22: MAE = Σ|y − ŷ| / n | B22: =I16/B20 -> 5938.5276 | C22: =M16/C20 -> 2369.704 | D22: =Q16/D20 -> 5149.4052 | E22: =U16/E20 -> 7356.5086 | F22: =Y16/F20 -> 4294.316
A23: RMSE = √(SSE / n) | B23: =SQRT(B21/B20) -> 7096.8875 | C23: =SQRT(C21/C20) -> 3740.3261 | D23: =SQRT(D21/D20) -> 6083.5883 | E23: =SQRT(E21/E20) -> 8349.9347 | F23: =SQRT(F21/F20) -> 5748.1902
A24: SST_test = Σ(y − ȳ_EDSA)² | B24: =DEVSQ($E$7:$E$15) -> 140428714 | C24: =DEVSQ($E$7:$E$15) -> 140428714 | D24: =DEVSQ($E$7:$E$15) -> 140428714 | E24: =DEVSQ($E$7:$E$15) -> 140428714 | F24: =DEVSQ($E$7:$E$15) -> 140428714
A25: Test R² = 1 − SSE/SST_test | B25: =1-B21/B24 -> -2.2279175 | C25: =1-C21/C24 -> 0.10338599 | D25: =1-D21/D24 -> -1.3719538 | E25: =1-E21/E24 -> -3.4684072 | F25: =1-F21/F24 -> -1.117624
A26: Σ |residuals| | B26: =I16 -> 53446.748 | C26: =M16 -> 21327.336 | D26: =Q16 -> 46344.647 | E26: =U16 -> 66208.577 | F26: =Y16 -> 38648.844
A27: Σ signed residuals (positive = under-prediction) | B27: =H16 -> 53446.748 | C27: =L16 -> -911.70181 | D27: =P16 -> 45547.726 | E27: =T16 -> 66208.577 | F27: =X16 -> 37985.657
A28: Avg actual crashes | B28: =AVERAGE($E$7:$E$15) -> 11122 | C28: =AVERAGE($E$7:$E$15) -> 11122 | D28: =AVERAGE($E$7:$E$15) -> 11122 | E28: =AVERAGE($E$7:$E$15) -> 11122 | F28: =AVERAGE($E$7:$E$15) -> 11122
A29: Median predicted crashes | B29: =MEDIAN(G7:G15) -> 5216.7241 | C29: =MEDIAN(K7:K15) -> 9952.7833 | D29: =MEDIAN(O7:O15) -> 5716.597 | E29: =MEDIAN(S7:S15) -> 3765.4914 | F29: =MEDIAN(W7:W15) -> 6854.5937
A30: Median accuracy = 1 − MAPE | B30: =AA16 -> 0.59568802 | C30: =AB16 -> 0.85370406 | D30: =AC16 -> 0.56029574 | E30: =AD16 -> 0.42437636 | F30: =AE16 -> 0.77252267
A31: Test years with accuracy ≥ 85% | B31: =COUNTIF(AA7:AA15,">=0.85") -> 0 | C31: =COUNTIF(AB7:AB15,">=0.85") -> 5 | D31: =COUNTIF(AC7:AC15,">=0.85") -> 1 | E31: =COUNTIF(AD7:AD15,">=0.85") -> 0 | F31: =COUNTIF(AE7:AE15,">=0.85") -> 3
A32: Volume accuracy = 1 − |Σ residuals| / Σ actual | B32: =1-ABS(B27)/$E$16 -> 0.46605578 | C32: =1-ABS(C27)/$E$16 -> 0.99089191 | D32: =1-ABS(D27)/$E$16 -> 0.54496867 | E32: =1-ABS(E27)/$E$16 -> 0.33856244 | F32: =1-ABS(F27)/$E$16 -> 0.62051532
A35: WORKED EXAMPLES – choose a test year (blue cell); every number below is pulled from the model sheets by formula
A36: Test year (2016–2024) | B36: 2019
A37: EDSA AADT | B37: =INDEX($B$7:$B$15,MATCH($B$36,$A$7:$A$15,0)) -> 405882
A38: Year | B38: =INDEX($A$7:$A$15,MATCH($B$36,$A$7:$A$15,0)) -> 2019
A39: Prev (actual crashes of the previous year) | B39: =INDEX($F$7:$F$15,MATCH($B$36,$A$7:$A$15,0)) -> 17276
A40: Total lanes-km | B40: =INDEX($D$7:$D$15,MATCH($B$36,$A$7:$A$15,0)) -> 285.6
A41: Actual crashes | B41: =INDEX($E$7:$E$15,MATCH($B$36,$A$7:$A$15,0)) -> 17382
A43: 1) LR – AADT only: ŷ = b₀ + b₁·AADT
A44: b₀ (intercept) | B44: =LR_CAL!B15 -> -686.56525
A45: b₁ × AADT | B45: =LR_CAL!B14*$B$37 -> 6242.4807
...

Sheet MODEL_COMPARISON
A1: MODEL_COMPARISON – Does previous crash history (and the other predictors) improve crash prediction? Ranked by EDSA test RMSE
A2: Every value is a formula linked to LR_CAL / RF_CAL / MLR_CALC / EDSA_TEST_ROAD. Lower error = better. Ranking uses EDSA TEST errors, never training R². Baselines are trained on the SAME 117 rows as the extended models.
A4: Model | B4: Predictor configuration | C4: Training observations | D4: Training R² | E4: Training MAE | F4: Training RMSE | G4: EDSA test SSE | H4: EDSA test MAE | I4: EDSA test RMSE | J4: EDSA test R² | K4: Sum of absolute residuals | L4: Sum of signed residuals | M4: Rank by EDSA test RMSE | N4: Rank by EDSA test MAE | O4: median accuracy (1 − MAPE) | P4: Test years ≥ 85% accurate (of 9) | Q4: Volume accuracy
A5: LR – AADT only (baseline) | B5: AADT | C5: =DATASETS!N9 -> 117 | D5: =LR_CAL!B18 -> 0.35456721 | E5: =LR_CAL!B19 -> 983.74255 | F5: =LR_CAL!B20 -> 1517.1941 | G5: =EDSA_TEST_ROAD!B21 -> 4.5329231e+08 | H5: =EDSA_TEST_ROAD!B22 -> 5938.5276 | I5: =EDSA_TEST_ROAD!B23 -> 7096.8875 | J5: =EDSA_TEST_ROAD!B25 -> -2.2279175 | K5: =EDSA_TEST_ROAD!B26 -> 53446.748 | L5: =EDSA_TEST_ROAD!B27 -> 53446.748 | M5: =RANK(I5,$I$5:$I$9,1) -> 4 | N5: =RANK(H5,$H$5:$H$9,1) -> 4 | O5: =EDSA_TEST_ROAD!B30 -> 0.59568802 | P5: =EDSA_TEST_ROAD!B31 -> 0 | Q5: =EDSA_TEST_ROAD!B32 -> 0.46605578
A6: LR – extended | B6: AADT, Year, Prev, LaneKm | C6: =DATASETS!N9 -> 117 | D6: =LR_CAL!B33 -> 0.87859111 | E6: =LR_CAL!B34 -> 396.39209 | F6: =LR_CAL!B35 -> 658.02269 | G6: =EDSA_TEST_ROAD!C21 -> 1.2591035e+08 | H6: =EDSA_TEST_ROAD!C22 -> 2369.704 | I6: =EDSA_TEST_ROAD!C23 -> 3740.3261 | J6: =EDSA_TEST_ROAD!C25 -> 0.10338599 | K6: =EDSA_TEST_ROAD!C26 -> 21327.336 | L6: =EDSA_TEST_ROAD!C27 -> -911.70181 | M6: =RANK(I6,$I$5:$I$9,1) -> 1 | N6: =RANK(H6,$H$5:$H$9,1) -> 1 | O6: =EDSA_TEST_ROAD!C30 -> 0.85370406 | P6: =EDSA_TEST_ROAD!C31 -> 5 | Q6: =EDSA_TEST_ROAD!C32 -> 0.99089191
A7: MLR – extended with road effects | B7: AADT, Year, Prev, Road effects (12 dummies) | C7: =DATASETS!N9 -> 117 | D7: =MLR_CALC!B90 -> 0.9245283 | E7: =MLR_CALC!B91 -> 352.72116 | F7: =MLR_CALC!B92 -> 518.80924 | G7: =EDSA_TEST_ROAD!D21 -> 3.3309042e+08 | H7: =EDSA_TEST_ROAD!D22 -> 5149.4052 | I7: =EDSA_TEST_ROAD!D23 -> 6083.5883 | J7: =EDSA_TEST_ROAD!D25 -> -1.3719538 | K7: =EDSA_TEST_ROAD!D26 -> 46344.647 | L7: =EDSA_TEST_ROAD!D27 -> 45547.726 | M7: =RANK(I7,$I$5:$I$9,1) -> 3 | N7: =RANK(H7,$H$5:$H$9,1) -> 3 | O7: =EDSA_TEST_ROAD!D30 -> 0.56029574 | P7: =EDSA_TEST_ROAD!D31 -> 1 | Q7: =EDSA_TEST_ROAD!D32 -> 0.54496867
A8: RF – AADT only (baseline) | B8: AADT | C8: =DATASETS!N9 -> 117 | D8: =RF_CAL!B31 -> 0.58568193 | E8: =RF_CAL!B32 -> 824.45577 | F8: =RF_CAL!B33 -> 1215.5772 | G8: =EDSA_TEST_ROAD!E21 -> 6.2749268e+08 | H8: =EDSA_TEST_ROAD!E22 -> 7356.5086 | I8: =EDSA_TEST_ROAD!E23 -> 8349.9347 | J8: =EDSA_TEST_ROAD!E25 -> -3.4684072 | K8: =EDSA_TEST_ROAD!E26 -> 66208.577 | L8: =EDSA_TEST_ROAD!E27 -> 66208.577 | M8: =RANK(I8,$I$5:$I$9,1) -> 5 | N8: =RANK(H8,$H$5:$H$9,1) -> 5 | O8: =EDSA_TEST_ROAD!E30 -> 0.42437636 | P8: =EDSA_TEST_ROAD!E31 -> 0 | Q8: =EDSA_TEST_ROAD!E32 -> 0.33856244
A9: RF – extended | B9: AADT, Year, Prev, LaneKm, Road one-hot (13) | C9: =DATASETS!N9 -> 117 | D9: =RF_CAL!C31 -> 0.93668938 | E9: =RF_CAL!C32 -> 340.64423 | F9: =RF_CAL!C33 -> 475.17535 | G9: =EDSA_TEST_ROAD!F21 -> 2.9737521e+08 | H9: =EDSA_TEST_ROAD!F22 -> 4294.316 | I9: =EDSA_TEST_ROAD!F23 -> 5748.1902 | J9: =EDSA_TEST_ROAD!F25 -> -1.117624 | K9: =EDSA_TEST_ROAD!F26 -> 38648.844 | L9: =EDSA_TEST_ROAD!F27 -> 37985.657 | M9: =RANK(I9,$I$5:$I$9,1) -> 2 | N9: =RANK(H9,$H$5:$H$9,1) -> 2 | O9: =EDSA_TEST_ROAD!F30 -> 0.77252267 | P9: =EDSA_TEST_ROAD!F31 -> 3 | Q9: =EDSA_TEST_ROAD!F32 -> 0.62051532
